Workbook

Sheet Coordinates
A1: Waypoint | B1: Coordinate NS | C1: Coordinate EW | D1: Altitude | E1: OPENNAV Bezeichung (https://opennav.com/waypoint/DE/MUN08)
A2: Airport Ref | B2: N 48 21 13,62 | C2: E 011 47 09,91
A3: AKINI | B3: N 48 44 59,00 | C3: E 012 07 27,00
A4: ALG | B4: N 47 59 51 | C4: E 010 15 44
A5: ALONU | B5: N 48 17 38 | C5: E 012 01 40
A6: AMEXO | B6: N 48 06 06 | C6: E 010 48 12
A7: AMPEG | B7: N 48 07 56 | C7: E 011 10 41
A8: ANKER | B8: N 48 34 21,45 | C8: E 012 00 08,38
A9: BEGEN | B9: N 48 19 10,32 | C9: E 011 28 53,40
A10: BIBAG | B10: N 48 23 49 | C10: E 012 44 59
A11: DM010 | B11: N 48 22 07,66 | C11: E 011 50 45,49
A12: DM011 | B12: N 48 23 05,66 | C12: E 011 53 03,65
A13: DM012 | B13: N 48 24 12,50 | C13: E 011 50 23,87
... A30: DM045 | B30: N 48 26 49,52 | C30: E 011 44 19,97
A31: DM046 | B31: N 48 14 58,79 | C31: E 011 24 47,92 | E31: DM059
A32: DM049 | B32: N 48 20 15,61 | C32: E 011 42 33,95
A33: DM050 | B33: N 48 17 15,25 | C33: E 011 42 28,82
A34: DM051 | B34: N 48 20 00,96 | C34: E 011 39 09,96
A35: DM052 | B35: N 48 19 54,66 | C35: E 011 37 45,60
A36: DM053 | B36: N 48 18 32,22 | C36: E 011 19 25,02 | E36: MSE18
A37: DM054 | B37: N 48 18 12,0 | C37: E 011 14 56,62
A38: DM055 | B38: N 48 25 33,53 | C38: E 011 26 25,72
A39: DM056 | B39: N 48 29 30,66 | C39: E 011 36 57,12
A40: DM057 | B40: N 48 32 19,19 | C40: E 011 59 09,84
A41: DM058 | B41: N 48 19 01,13 | C41: E 011 25 49,15 | E41: MSE14
A42: DM060 | B42: N 48 21 26,90 | C42: E 011 42 18,56 | E42: MNE36
A43: DM061 | B43: N 48 19 40,25 | C43: E 011 18 13,41
A44: DM062 | B44: N 48 19 17,15 | C44: E 011 13 16,68
A45: DM063 | B45: N 48 27 28,44 | C45: E 011 25 54,01
A46: DM064 | B46: N 48 29 32,67 | C46: E 011 37 13,52
A47: DM065 | B47: N 48 34 12,81 | C47: E 011 35 51,01
A48: DM066 | B48: N 48 21 17,69 | C48: E 011 39 39,11
A49: DM067 | B49: N 48 21 29,94 | C49: E 011 42 3,07
A50: DM068 | B50: N 48 13 48,80 | C50: E 011 42 22,95
A51: DM069 | B51: N 48 05 40,53 | C51: E 011 44 20,87
A52: DM070 | B52: N 48 22 07,04 | C52: E 011 50 37,92
A53: DM071 | B53: N 48 22 47,43 | C53: E 011 59 33,87
A54: DM072 | B54: N 48 20 29,15 | C54: E 012 02 01,38 | E54: DM074
A55: DM073 | B55: N 48 25 03,03 | C55: E 011 51 59,06
A56: DM076 | B56: N 48 23 48,53 | C56: E 011 51 57,92
...

Sheet Approaches
A1: Name | B1: Climb Gradient | C1: Waypoint Name | D1: Remark | E1: Waypoint row#
A2: APCH 08L | B2: 5,2% | C2: MIQ | D2: Altitude: 5000 | E2: =MATCH(C2,Coordinates!$A$2:$A$114,0) -> 96
C3: DM421 | E3: =MATCH(C3,Coordinates!$A$2:$A$114,0) -> 71
C4: DM431 | E4: =MATCH(C4,Coordinates!$A$2:$A$114,0) -> 73
C5: MAGAT | E5: =MATCH(C5,Coordinates!$A$2:$A$114,0) -> 91
C6: RWY 08L | E6: =MATCH(C6,Coordinates!$A$2:$A$114,0) -> 106
A7: APCH 08R | B7: 5,2% | C7: OTT | D7: Altitude: 5000 | E7: =MATCH(C7,Coordinates!$A$2:$A$114,0) -> 102
C8: DM451 | E8: =MATCH(C8,Coordinates!$A$2:$A$114,0) -> 77
C9: DM441 | E9: =MATCH(C9,Coordinates!$A$2:$A$114,0) -> 75
C10: BEGEN | E10: =MATCH(C10,Coordinates!$A$2:$A$114,0) -> 8
C11: RWY 08R | E11: =MATCH(C11,Coordinates!$A$2:$A$114,0) -> 107
A12: APCH 26L | B12: 5,2% | C12: OTT | D12: Altitude: 5000 | E12: =MATCH(C12,Coordinates!$A$2:$A$114,0) -> 102
C13: DM458 | E13: =MATCH(C13,Coordinates!$A$2:$A$114,0) -> 78
C14: DM448 | E14: =MATCH(C14,Coordinates!$A$2:$A$114,0) -> 76
C15: NELBI | E15: =MATCH(C15,Coordinates!$A$2:$A$114,0) -> 99
C16: RWY 26L | E16: =MATCH(C16,Coordinates!$A$2:$A$114,0) -> 108
A17: APCH 26R | B17: 5,2% | C17: MIQ | D17: Altitude: 5000 | E17: =MATCH(C17,Coordinates!$A$2:$A$114,0) -> 96
C18: DM428 | E18: =MATCH(C18,Coordinates!$A$2:$A$114,0) -> 72
C19: DM438 | E19: =MATCH(C19,Coordinates!$A$2:$A$114,0) -> 74
C20: GUDEG | E20: =MATCH(C20,Coordinates!$A$2:$A$114,0) -> 86
C21: RWY 26R | E21: =MATCH(C21,Coordinates!$A$2:$A$114,0) -> 109

Sheet SID 08L
A1: Name | B1: Climb Gradient | C1: Waypoint Name | D1: Remark | E1: Waypoint row#
A2: GIVMI 6Q (min) | B2: STD | C2: RWY 26R | E2: =MATCH(C2,Coordinates!$A$2:$A$114,0) -> 109
C3: DM070 | E3: =MATCH(C3,Coordinates!$A$2:$A$114,0) -> 51
C4: DM073 | E4: =MATCH(C4,Coordinates!$A$2:$A$114,0) -> 54
C5: MIQ | E5: =MATCH(C5,Coordinates!$A$2:$A$114,0) -> 96
C6: GIVMI | E6: =MATCH(C6,Coordinates!$A$2:$A$114,0) -> 85
A7: GIVMI 6Q (max) | B7: STD | C7: RWY 26R | E7: =MATCH(C7,Coordinates!$A$2:$A$114,0) -> 109
C8: DME DMN 4,5 | E8: =MATCH(C8,Coordinates!$A$2:$A$114,0) -> #N/A
C9: DM073 | E9: =MATCH(C9,Coordinates!$A$2:$A$114,0) -> 54
C10: MIQ | E10: =MATCH(C10,Coordinates!$A$2:$A$114,0) -> 96
C11: GIVMI | E11: =MATCH(C11,Coordinates!$A$2:$A$114,0) -> 85
A12: RIDAR 7Q (min) | B12: STD | C12: RWY 26R | E12: =MATCH(C12,Coordinates!$A$2:$A$114,0) -> 109
C13: DM070 | E13: =MATCH(C13,Coordinates!$A$2:$A$114,0) -> 51
C14: DM073 | E14: =MATCH(C14,Coordinates!$A$2:$A$114,0) -> 54
C15: MIQ | E15: =MATCH(C15,Coordinates!$A$2:$A$114,0) -> 96
C16: WLD | E16: =MATCH(C16,Coordinates!$A$2:$A$114,0) -> 113
C17: RIDAR | E17: =MATCH(C17,Coordinates!$A$2:$A$114,0) -> 104
A18: RIDAR 7Q (max) | B18: STD | C18: RWY 26R | E18: =MATCH(C18,Coordinates!$A$2:$A$114,0) -> 109
C19: DME DMN 4,5 | E19: =MATCH(C19,Coordinates!$A$2:$A$114,0) -> #N/A
C20: DM073 | E20: =MATCH(C20,Coordinates!$A$2:$A$114,0) -> 54
C21: MIQ | E21: =MATCH(C21,Coordinates!$A$2:$A$114,0) -> 96
C22: WLD | E22: =MATCH(C22,Coordinates!$A$2:$A$114,0) -> 113
C23: RIDAR | E23: =MATCH(C23,Coordinates!$A$2:$A$114,0) -> 104
A24: ALG 2Q | B24: 3,4% until 3700 | C24: RWY 26R | E24: =MATCH(C24,Coordinates!$A$2:$A$114,0) -> 109
C25: DM071 | E25: =MATCH(C25,Coordinates!$A$2:$A$114,0) -> 52
C26: DM094 | E26: =MATCH(C26,Coordinates!$A$2:$A$114,0) -> 70
C27: LAKOL | E27: =MATCH(C27,Coordinates!$A$2:$A$114,0) -> 89
C28: OBAXA | E28: =MATCH(C28,Coordinates!$A$2:$A$114,0) -> 100
C29: MERSI | E29: =MATCH(C29,Coordinates!$A$2:$A$114,0) -> 95
C30: ALG | E30: =MATCH(C30,Coordinates!$A$2:$A$114,0) -> 3
A31: MERSI 2T | B31: 7,0% until 7000 | C31: RWY 26R | E31: =MATCH(C31,Coordinates!$A$2:$A$114,0) -> 109
C32: DM071 | E32: =MATCH(C32,Coordinates!$A$2:$A$114,0) -> 52
C33: DM072 | E33: =MATCH(C33,Coordinates!$A$2:$A$114,0) -> 53
C34: DM090 | E34: =MATCH(C34,Coordinates!$A$2:$A$114,0) -> 66
C35: OTT | E35: =MATCH(C35,Coordinates!$A$2:$A$114,0) -> 102
C36: OBAXA | E36: =MATCH(C36,Coordinates!$A$2:$A$114,0) -> 100
C37: MERSI | E37: =MATCH(C37,Coordinates!$A$2:$A$114,0) -> 95
A38: MERSI 4Q | B38: 3,4% until 3700 | C38: RWY 26R | E38: =MATCH(C38,Coordinates!$A$2:$A$114,0) -> 109
C39: DM071 | E39: =MATCH(C39,Coordinates!$A$2:$A$114,0) -> 52
C40: DM094 | E40: =MATCH(C40,Coordinates!$A$2:$A$114,0) -> 70
...

Sheet SID 08R
A1: Name | B1: Climb Gradient | C1: Waypoint Name | D1: Remark | E1: Waypoint row#
A2: GIVMI 6E (min) | B2: STD | C2: RWY 26L | E2: =MATCH(C2,Coordinates!$A$2:$A$114,0) -> 108
C3: DM084 | E3: =MATCH(C3,Coordinates!$A$2:$A$114,0) -> 61
C4: DM085 | E4: =MATCH(C4,Coordinates!$A$2:$A$114,0) -> 62
C5: MIQ | E5: =MATCH(C5,Coordinates!$A$2:$A$114,0) -> 96
C6: GIVMI | E6: =MATCH(C6,Coordinates!$A$2:$A$114,0) -> 85
A7: GIVMI 6E (max) | B7: STD | C7: RWY 26L | E7: =MATCH(C7,Coordinates!$A$2:$A$114,0) -> 108
C8: DME DMS 5,1 | E8: =MATCH(C8,Coordinates!$A$2:$A$114,0) -> #N/A
C9: DM085 | E9: =MATCH(C9,Coordinates!$A$2:$A$114,0) -> 62
C10: MIQ | E10: =MATCH(C10,Coordinates!$A$2:$A$114,0) -> 96
C11: GIVMI | E11: =MATCH(C11,Coordinates!$A$2:$A$114,0) -> 85
A12: RIDAR 7E (min) | B12: STD | C12: RWY 26L | E12: =MATCH(C12,Coordinates!$A$2:$A$114,0) -> 108
C13: DM084 | E13: =MATCH(C13,Coordinates!$A$2:$A$114,0) -> 61
C14: DM085 | E14: =MATCH(C14,Coordinates!$A$2:$A$114,0) -> 62
C15: MIQ | E15: =MATCH(C15,Coordinates!$A$2:$A$114,0) -> 96
C16: WLD | E16: =MATCH(C16,Coordinates!$A$2:$A$114,0) -> 113
C17: RIDAR | E17: =MATCH(C17,Coordinates!$A$2:$A$114,0) -> 104
A18: RIDAR 7E (max) | B18: STD | C18: RWY 26L | E18: =MATCH(C18,Coordinates!$A$2:$A$114,0) -> 108
C19: DME DMS 5,1 | E19: =MATCH(C19,Coordinates!$A$2:$A$114,0) -> #N/A
C20: DM085 | E20: =MATCH(C20,Coordinates!$A$2:$A$114,0) -> 62
C21: MIQ | E21: =MATCH(C21,Coordinates!$A$2:$A$114,0) -> 96
C22: WLD | E22: =MATCH(C22,Coordinates!$A$2:$A$114,0) -> 113
C23: RIDAR | E23: =MATCH(C23,Coordinates!$A$2:$A$114,0) -> 104
A24: ALG 2E | B24: 3,8% until 3700 | C24: RWY 26L | E24: =MATCH(C24,Coordinates!$A$2:$A$114,0) -> 108
C25: DM081 | E25: =MATCH(C25,Coordinates!$A$2:$A$114,0) -> 59
C26: ALONU | E26: =MATCH(C26,Coordinates!$A$2:$A$114,0) -> 4
C27: LAKOL | E27: =MATCH(C27,Coordinates!$A$2:$A$114,0) -> 89
C28: OBAXA | E28: =MATCH(C28,Coordinates!$A$2:$A$114,0) -> 100
C29: MERSI | E29: =MATCH(C29,Coordinates!$A$2:$A$114,0) -> 95
C30: ALG | E30: =MATCH(C30,Coordinates!$A$2:$A$114,0) -> 3
A31: MERSI 2P | B31: 9,4% until 7000 | C31: RWY 26L | E31: =MATCH(C31,Coordinates!$A$2:$A$114,0) -> 108
C32: DM081 | E32: =MATCH(C32,Coordinates!$A$2:$A$114,0) -> 59
C33: DM087 | E33: =MATCH(C33,Coordinates!$A$2:$A$114,0) -> 63
C34: DM090 | E34: =MATCH(C34,Coordinates!$A$2:$A$114,0) -> 66
C35: OTT | E35: =MATCH(C35,Coordinates!$A$2:$A$114,0) -> 102
C36: OBAXA | E36: =MATCH(C36,Coordinates!$A$2:$A$114,0) -> 100
C37: MERSI | E37: =MATCH(C37,Coordinates!$A$2:$A$114,0) -> 95
A38: MERSI 4E | B38: 3,8% until 3700 | C38: RWY 26L | E38: =MATCH(C38,Coordinates!$A$2:$A$114,0) -> 108
C39: DM081 | E39: =MATCH(C39,Coordinates!$A$2:$A$114,0) -> 59
C40: ALONU | E40: =MATCH(C40,Coordinates!$A$2:$A$114,0) -> 4
...

Sheet SID 26L
A1: Name | B1: Climb Gradient | C1: Waypoint Name | D1: Remark | E1: Waypoint row#
A2: GIVMI 6S | B2: STD | C2: RWY 08R | E2: =MATCH(C2,Coordinates!$A$2:$A$114,0) -> 107
C3: DM052 | E3: =MATCH(C3,Coordinates!$A$2:$A$114,0) -> 34
C4: DM055 | E4: =MATCH(C4,Coordinates!$A$2:$A$114,0) -> 37
C5: GIVMI | E5: =MATCH(C5,Coordinates!$A$2:$A$114,0) -> 85
A6: MIQ 8S | B6: STD | C6: RWY 08R | E6: =MATCH(C6,Coordinates!$A$2:$A$114,0) -> 107
C7: DME DMS 3,1 | E7: =MATCH(C7,Coordinates!$A$2:$A$114,0) -> #N/A
C8: MIQ | E8: =MATCH(C8,Coordinates!$A$2:$A$114,0) -> 96
A9: RIDAR 6S | B9: 4,9% until 7000 | C9: RWY 08R | E9: =MATCH(C9,Coordinates!$A$2:$A$114,0) -> 107
C10: DM052 | E10: =MATCH(C10,Coordinates!$A$2:$A$114,0) -> 34
C11: DM053 | E11: =MATCH(C11,Coordinates!$A$2:$A$114,0) -> 35
C12: DM054 | E12: =MATCH(C12,Coordinates!$A$2:$A$114,0) -> 36
C13: RIDAR | E13: =MATCH(C13,Coordinates!$A$2:$A$114,0) -> 104
A14: OLASO 2S | B14: 5,3% until 7000 | C14: RWY 08R | E14: =MATCH(C14,Coordinates!$A$2:$A$114,0) -> 107
C15: MSE | E15: =MATCH(C15,Coordinates!$A$2:$A$114,0) -> 98
C16: DM053 | E16: =MATCH(C16,Coordinates!$A$2:$A$114,0) -> 35
C17: OLASO | E17: =MATCH(C17,Coordinates!$A$2:$A$114,0) -> 101
A18: MERSI 5S | B18: 5,3% until 7000 | C18: RWY 08R | E18: =MATCH(C18,Coordinates!$A$2:$A$114,0) -> 107
C19: MSE | E19: =MATCH(C19,Coordinates!$A$2:$A$114,0) -> 98
C20: DM053 | E20: =MATCH(C20,Coordinates!$A$2:$A$114,0) -> 35
C21: AMPEG | E21: =MATCH(C21,Coordinates!$A$2:$A$114,0) -> 6
C22: MERSI | E22: =MATCH(C22,Coordinates!$A$2:$A$114,0) -> 95
A23: ALG 2S | B23: 5,3% until 7000 | C23: RWY 08R | E23: =MATCH(C23,Coordinates!$A$2:$A$114,0) -> 107
C24: MSE | E24: =MATCH(C24,Coordinates!$A$2:$A$114,0) -> 98
C25: DM053 | E25: =MATCH(C25,Coordinates!$A$2:$A$114,0) -> 35
C26: AMEXO | E26: =MATCH(C26,Coordinates!$A$2:$A$114,0) -> 5
C27: ALG | E27: =MATCH(C27,Coordinates!$A$2:$A$114,0) -> 3
A28: OBAXA 6S (min) | B28: STD | C28: RWY 08R | E28: =MATCH(C28,Coordinates!$A$2:$A$114,0) -> 107
C29: DM049 | E29: =MATCH(C29,Coordinates!$A$2:$A$114,0) -> 31
C30: DM068 | E30: =MATCH(C30,Coordinates!$A$2:$A$114,0) -> 49
C31: DM069 | E31: =MATCH(C31,Coordinates!$A$2:$A$114,0) -> 50
C32: OBAXA | E32: =MATCH(C32,Coordinates!$A$2:$A$114,0) -> 100
A33: OBAXA 6S (max) | B33: STD | C33: RWY 08R | E33: =MATCH(C33,Coordinates!$A$2:$A$114,0) -> 107
C34: DME DMS 4,5 | E34: =MATCH(C34,Coordinates!$A$2:$A$114,0) -> #N/A
C35: DM068 | E35: =MATCH(C35,Coordinates!$A$2:$A$114,0) -> 49
C36: DM069 | E36: =MATCH(C36,Coordinates!$A$2:$A$114,0) -> 50
C37: OBAXA | E37: =MATCH(C37,Coordinates!$A$2:$A$114,0) -> 100
A38: TULSI 7S (min) | B38: STD | C38: RWY 08R | E38: =MATCH(C38,Coordinates!$A$2:$A$114,0) -> 107
C39: DM049 | E39: =MATCH(C39,Coordinates!$A$2:$A$114,0) -> 31
C40: DM050 | E40: =MATCH(C40,Coordinates!$A$2:$A$114,0) -> 32
...

Sheet SID 26R
A1: Name | B1: Climb Gradient | C1: Waypoint Name | D1: Remark | E1: Waypoint row#
A2: GIVMI 1N | B2: STD | C2: RWY 08L | E2: =MATCH(C2,Coordinates!$A$2:$A$114,0) -> 106
C3: DM060 | E3: =MATCH(C3,Coordinates!$A$2:$A$114,0) -> 41
C4: DM063 | E4: =MATCH(C4,Coordinates!$A$2:$A$114,0) -> 44
C5: GIVMI | E5: =MATCH(C5,Coordinates!$A$2:$A$114,0) -> 85
A6: MIQ 9N | B6: STD | C6: RWY 08L | E6: =MATCH(C6,Coordinates!$A$2:$A$114,0) -> 106
C7: DME DMN 3,5 | E7: =MATCH(C7,Coordinates!$A$2:$A$114,0) -> #N/A
C8: MIQ | E8: =MATCH(C8,Coordinates!$A$2:$A$114,0) -> 96
A9: RIDAR 6N | B9: 4,9% until 7000 | C9: RWY 08L | E9: =MATCH(C9,Coordinates!$A$2:$A$114,0) -> 106
C10: MNE | E10: =MATCH(C10,Coordinates!$A$2:$A$114,0) -> 97
C11: DM061 | E11: =MATCH(C11,Coordinates!$A$2:$A$114,0) -> 42
C12: DM062 | E12: =MATCH(C12,Coordinates!$A$2:$A$114,0) -> 43
C13: RIDAR | E13: =MATCH(C13,Coordinates!$A$2:$A$114,0) -> 104
A14: OLASO 2N | B14: 5,3% until 7000 | C14: RWY 08L | E14: =MATCH(C14,Coordinates!$A$2:$A$114,0) -> 106
C15: MNE | E15: =MATCH(C15,Coordinates!$A$2:$A$114,0) -> 97
C16: DM061 | E16: =MATCH(C16,Coordinates!$A$2:$A$114,0) -> 42
C17: OLASO | E17: =MATCH(C17,Coordinates!$A$2:$A$114,0) -> 101
A18: MERSI 6N | B18: 5,3% until 7000 | C18: RWY 08L | E18: =MATCH(C18,Coordinates!$A$2:$A$114,0) -> 106
C19: MNE | E19: =MATCH(C19,Coordinates!$A$2:$A$114,0) -> 97
C20: DM061 | E20: =MATCH(C20,Coordinates!$A$2:$A$114,0) -> 42
C21: AMPEG | E21: =MATCH(C21,Coordinates!$A$2:$A$114,0) -> 6
C22: MERSI | E22: =MATCH(C22,Coordinates!$A$2:$A$114,0) -> 95
A23: ALG 2N | B23: 5,3% until 7000 | C23: RWY 08L | E23: =MATCH(C23,Coordinates!$A$2:$A$114,0) -> 106
C24: MNE | E24: =MATCH(C24,Coordinates!$A$2:$A$114,0) -> 97
C25: DM061 | E25: =MATCH(C25,Coordinates!$A$2:$A$114,0) -> 42
C26: AMEXO | E26: =MATCH(C26,Coordinates!$A$2:$A$114,0) -> 5
C27: ALG | E27: =MATCH(C27,Coordinates!$A$2:$A$114,0) -> 3
A28: OBAXA 6N (min) | B28: STD | C28: RWY 08L | E28: =MATCH(C28,Coordinates!$A$2:$A$114,0) -> 106
C29: DM067 | E29: =MATCH(C29,Coordinates!$A$2:$A$114,0) -> 48
C30: DM050 | E30: =MATCH(C30,Coordinates!$A$2:$A$114,0) -> 32
C31: DM068 | E31: =MATCH(C31,Coordinates!$A$2:$A$114,0) -> 49
C32: DM069 | E32: =MATCH(C32,Coordinates!$A$2:$A$114,0) -> 50
C33: OBAXA | E33: =MATCH(C33,Coordinates!$A$2:$A$114,0) -> 100
A34: OBAXA 6S (max) | B34: STD | C34: RWY 08L | E34: =MATCH(C34,Coordinates!$A$2:$A$114,0) -> 106
C35: DME DMS 5,0 | E35: =MATCH(C35,Coordinates!$A$2:$A$114,0) -> #N/A
C36: DM050 | E36: =MATCH(C36,Coordinates!$A$2:$A$114,0) -> 32
C37: DM068 | E37: =MATCH(C37,Coordinates!$A$2:$A$114,0) -> 49
C38: DM069 | E38: =MATCH(C38,Coordinates!$A$2:$A$114,0) -> 50
C39: OBAXA | E39: =MATCH(C39,Coordinates!$A$2:$A$114,0) -> 100
A40: TULSI 4N (min) | B40: STD | C40: RWY 08L | E40: =MATCH(C40,Coordinates!$A$2:$A$114,0) -> 106
...
